<?xml version="1.0"?>
<robot xmlns:xacro="http://www.ros.org/wiki/xacro">

<!-- Базовая ссылка -->
    <link name="base_link">
    </link>

    <!-- Шасси -->
    <joint name="chassis_joint" type="fixed">
        <parent link="base_link"/>
        <child link="chassis"/>
        <origin xyz="0 0 0"/>
    </joint>

    <link name="chassis">
        <visual>
            <origin xyz="0 0 0.035"/>
            <geometry>
                <cylinder radius="0.17" length="0.07"/>
            </geometry>
        </visual>
    </link>

    <!-- Левое колесо -->
    <joint name="left_wheel_joint" type="continuous">
        <parent link="base_link"/>
        <child link="left_wheel"/>
        <origin xyz="0 0.115 0"/>
        <axis xyz="0 1 0"/>
    </joint>

    <link name="left_wheel">
        <visual>
            <origin xyz="0 0 0" rpy="${pi/2} 0 0"/>
            <geometry>
                <cylinder radius="0.035" length="0.02"/> 
            </geometry>
        </visual>
    </link>

    <!-- Правое колесо -->
    <joint name="right_wheel_joint" type="continuous">
        <parent link="base_link"/>
        <child link="right_wheel"/>
        <origin xyz="0 -0.115 0"/>
        <axis xyz="0 1 0"/>
    </joint>

    <link name="right_wheel">
        <visual>
            <origin xyz="0 0 0" rpy="${pi/2} 0 0"/>
            <geometry>
                <cylinder radius="0.035" length="0.02"/>
            </geometry>
        </visual>
    </link>

    <!-- Переднее колесо -->
    <joint name="caster_wheel_joint" type="fixed">
        <parent link="chassis"/>
        <child link="caster_wheel"/>
        <origin xyz="0.115 0 0"/>
    </joint>

    <link name="caster_wheel">
        <visual>
            <geometry>
                <sphere radius="0.035"/>
            </geometry>
        </visual>
    </link>

</robot>